Workbook
Name A: #REF!
Name Akses_yang_sempit: 'New Listis '!$A$2:$A$10
Name Area_ATEX: 'New Listis '!$AK$2
Name Asbestos: 'New Listis '!$B$2:$B$3
Name Bagian_peralatan_yang_menonjol: 'New Listis '!$C$2:$C$10
Name Bagian_yang_bergerak: 'New Listis '!$D$2:$D$10
Name Bahan_Kimia_berbahaya: 'New Listis '!$E$2:$E$10
Name Bahan_peledak: 'New Listis '!$F$2:$F$10
Name Bahaya_listrik: 'New Listis '!$G$2:$G$10
Name Bahaya_suhu_rendah: 'New Listis '!$H$2:$H$10
Name Bahaya_suhu_tinggi: 'New Listis '!$I$2:$I$10
Name Beban_di_atas_kepala: 'New Listis '!$J$2:$J$10
Name Beban_pengangkatan_tidak_pada_titik_center: 'New Listis '!$K$2:$K$10
Name Bekerja_di_area_lalu_lalang_kendaraan: 'New Listis '!$L$2:$L$10
Name Bekerja_di_ketinggian: 'New Listis '!$M$2:$M$10
Name Benda_jatuh: 'New Listis '!$N$2:$N$10
Name Compressed_gas_atau_air: 'New Listis '!$O$2:$O$10
Name Dampak_Biologi: 'New Listis '!$P$2:$P$10
Name Debu_atau_partikel_lainnya: 'New Listis '!$Q$2:$Q$10
Name Elemen_tajam: 'New Listis '!$R$2:$R$10
Name Flashes_atau_Sinar_Berkedip: 'New Listis '!$S$2:$S$10
Name Forklift_dan_mesin_industri_lainnya: 'New Listis '!$T$2:$T$10
Name Gerakan_anggot__tubuh_ke_atas_yang_berulang: 'New Listis '!$U$2:$U$10
Name Gesekan: 'New Listis '!$V$2:$V$10
Name Getaran_pada_tangan: 'New Listis '!$W$2:$W$10
Name Getaran_pada_tubuh: 'New Listis '!$X$2:$X$10
Name Halangan_di_atas_kepala: 'New Listis '!$Y$2:$Y$10
Name Hazards: Listis!$A$2:$A$45
Name Kebisingan: 'New Listis '!$Z$2:$Z$10
Name Manual_Handling: 'New Listis '!$AB$2:$AB$10
Name Material_radioaktif: 'New Listis '!$AA$2:$AA$10
Name Pekerjaan_panas: 'New Listis '!$AJ$2:$AJ$10
Name Penerangan: 'New Listis '!$AC$2:$AC$10
Name Peralatan_belum_di_cek: 'New Listis '!$AH$2:$AH$10
Name Permukaan_dingin: 'New Listis '!$AD$2:$AD$10
Name Permukaan_licin: 'New Listis '!$AE$2:$AE$10
Name Permukaan_panas: 'New Listis '!$AF$2:$AF$10
Name Risks: Listis!$B$2:$B$22
Name Ruang_Terbatas: 'New Listis '!$AL$2:$AL$10
Name Stress_berhubungan_dengan_pekerjaan: 'New Listis '!$AG$2:$AG$10
Name ValidateChangeInDialogSelection: Listis!ValidateChangeInDialogSelection
Name zat_yang_mudah_terbakar: 'New Listis '!$AI$2:$AI$10
Name Опасности: Listis!$A$2:$A$45
Name Результаты: [1]Списки!$A$2:$A$18
Name Риски: Listis!$B$2:$B$22
Name Тело: [1]Списки!$B$2:$B$24

Sheet Lookup Table (2)
A2: Probability (P) | D2: Severity (S) | I2: Risk Rating | K2: Hierarchy of controls | L2: Effectiveness of Control Measures | N2: Example/ Notes | O2: Risk Matrix
A3: Rare | B3: Conceivably possible, but not aware of it happening before | C3: 1 | D3: Minor | E3: First Aid Case | F3: Minor Reversible Health Effects | G3: Less than $10K | H3: 1 | I3: 1-2 | J3: Low | K3: Elimination/ Substitution | L3: Elimination or substitution (Substitition requieres a re-assessment) | M3: 0 | N3: Elimination_ Manual handling of minor ingredient eliminated with reformulation replaces ingredient with another already handled in bulk system | O3: Probability | P3: Minor | Q3: Moderate | R3: Serious | S3: Catastrophic | U3: Low | V3: Acceptable Risk Level • Does not require active management
A4: Unlikely | B4: Could happen under abnormal circumstances but not expected | C4: 2 | D4: Moderate | E4: Medical Treatment Case (MTC) Restricted Work Case (RWC) Loss of consciousness | F4: Restricted Work Disease | G4: Liabilities in the $10K -$100K range. | H4: 2 | I4: 3-7 | J4: Moderate | K4: Engineering Controls | L4: Controls that Do Not require Admin intervention, Training, Signage and PPE | M4: 0.3 | N4: - Guards with Cat 3 or 4 interlocks, restart by separate button, (without line of sight) and Pressure Sensing Devices or Trapped Key system (if person is able to stay within cage area) - Physical barrriers (fixed guards, cage, wall, isolated aisles, etc.) | O4: Rare | P4: Low | Q4: Low | R4: Moderate | S4: High | U4: Moderate | V4: Acceptable Risk Level • Additional measures could be used to reduce the risk further. • Notification might be needed in case help is required for further risk reduction / monitoring. • Monitoring must be done by Site EHS team at least every three years
A5: Likely | B5: Reasonably expected to happen | C5: 3 | D5: Serious | E5: Lost time injury (LTI) Lost time occupational injury Permanent injury or illness | F5: Major Reversible Health Effects | G5: Liabilities in the $100K-$1M range. | H5: 4 | I5: 8-15 | J5: High | K5: Admin, training, PPE | L5: Controls that Do require Admin intervention OR Admin controls (i.e. training, signage and PPE) | M5: 0.6 | N5: - LOTO - Guards with Cat 1 or 2 interlocks, 2 points of control and tool/PPE - Guards with Cat 3 or 4 interlocks, with auto-restart, 2 points of control and tools/PPE - Energy isolation (pneumatic, hydraulic, electrical, etc.) | O5: Unlikely | P5: Low | Q5: Moderate | R5: High | S5: High | U5: High | V5: Non-Acceptable Risk Level • Additional Temporary controls are implemented until permanent corrective action can be implemented. • A plan must include the specific actions and schedule to address the risk, the active monitoring and assessment of the effectiveness of the treatment. • Notification to BU Manager. • Monitoring must be done by Site EHS team at least once per year. If further Risk Reduction cannot be achieved, ALARP principle must be demonstrated and properly communicated
A6: Almost certain | B6: Expected situation which will happen | C6: 5 | D6: Catastrophic | E6: Fatality / Multiple fatalities | F6: Permanent Disability on the basis of Health Fatal Diseases | G6: Material liability over $1M. | H6: 8 | I6: 16-39 | J6: Critical | K6: PPE | L6: PPE as required to address physical hazards | M6: 0.9 | N6: Gloves, bump cap, gloves, eyeware, etc. | O6: Likely | P6: Moderate | Q6: Moderate | R6: High | S6: Critical | U6: Critical | V6: Non-Acceptable Risk Level • Additional interim controls are implemented until permanent corrective action can be implemented. • A plan must include the specific actions and schedule to address the risk, on-going monitoring and assessment of the effectiveness of the treatment. • Notification to Manufacturing Director • Monitoring must be done by Site EHS team at least once every six months. If further Risk Reduction cannot be achieved, ALARP principle must be demonstrated and properly communicated
I7: >=40 | J7: Catastrophic | K7: No controls | L7: No Controls | M7: 1 | N7: No Controls | O7: Almost Certain | P7: Moderate | Q7: High | R7: Critical | S7: Catastrophic | U7: Catastrophic | V7: Non-Acceptable Risk Level • Stop operations until controls are in place to minimize the risk level • Notification to Manufacturing Director • On-going monitoring must be done by Site EHS team. If further Risk Reduction cannot be achieved, ALARP principle must be demonstrated and properly communicated

Sheet New Template
B2: PT. HM SAMPOERNA Tbk. | O2: QR/MNFPRJ/002
B3: FORMULIR JOB SAFETY ANALYSIS (JSA) | O3: 1 | AG3: Eliminasi | AH3: Percepatan , perlambatan | AI3: Arc | AJ3: Ledakan | AK3: Fenomena kavitasi | AL3: Fenomena Kavitasi | AM3: Sumber radiasi pengion | AN3: Aerosol | AO3: Akses | AP3: Debu dan embun | AQ3: Lama jam kerja tidak normal | AR3: Tanah yang tidak rata atau rusak | AY3: Kolom N | AZ3: Kolom L | BE3: Kolom Q | BR3: Probability | BS3: D | BT3: C | BU3: B | BV3: A
O4: 1 | AG4: Substitusi | AH4: Energi kinetik | AI4: Fenomena elektromagnetik | AJ4: Nyala api | AK4: Exhausting system | AL4: Bagian yang bergerak mengalami ketidaklurusan antar kedua poros(Misalighment) | AM4: Rendahnya radiasi frekuensi elektromagnetik | AN4: Biologi and mikrobiologi(virus atau bacteri) | AO4: Desain atau lokasi indikator dan unit tampilan visual | AP4: Gangguan elektromagnetik | AQ4: Perilaku yang agresif | AR4: Wet / Slick / Slippery Conditions | AV4: D | AW4: 1 | AX4: Eliminasi | AY4: 0 | AZ4: Low | BA4: 2 | BD4: 0-3 | BE4: Low | BF4: 3 | BG4: Low | BR4: 4 | BS4: Moderate | BT4: High | BU4: Critical | BV4: Catastrophic
A5: No.Izin/Permit No. | C5: : | F5: Dibuat Oleh | K5: Diperiksa dan Disetujui Oleh | AG5: Engineering Control | AH5: Bagian sudut | AI5: Fenomena elektrostatistik | AJ5: Objek dan material dengan suhu tinggi atau rendah | AK5: Kebocoran gas bertekanan tinggi | AL5: Peralatan seluler | AM5: Radiasi optik (inframerah, terlihat dan ultraviolet), termasuk laser | AN5: Mudah terbakar | AO5: Desain, lokasi, atau identifikasi perangkat kontrol | AP5: Pencahayaan lokal | AQ5: pengaruh alkohol atau obat/narkoba | AR5: Ketinggian dari permukaan tanah | AV5: C | AW5: 2 | AX5: Substitusi | AY5: 0.3 | AZ5: Moderate | BA5: 4 | BD5: 3-5.9 | BE5: Moderate | BF5: 4 | BG5: Moderate | BR5: 3 | BS5: Moderate | BT5: Moderate | BU5: High | BV5: Critical
F6: Prepared By | K6: Reviewed and Approved By | AG6: Administrasi Control | AH6: Pendekatan elemen bergerak ke bagian tetap | AI6: Komponen / bagian yang hidup atau menyala | AJ6: Radiasi dari sumber panas | AK6: Proses pembuatan (stamping, cutting, dll.) | AL6: Pengikisan permukaan | AM6: Radiasi elektromagnetik frekuensi radio | AN6: Debu | AO6: Kekuatan | AP6: Kilat / Petir | AQ6: Pelecehan | AR6: Beban jatuh | AV6: B | AW6: 3 | AX6: Engineering Control | AY6: 0.6 | AZ6: High | BA6: 6 | BD6: 5.9-7 | BE6: High | BF6: 6 | BG6: High | BR6: 2 | BS6: Low | BT6: Moderate | BU6: High | BV6: High
A7: Perusahaan / Company | C7: : PT. Satria Piranti perkasa | F7: Project Group Leader (Permit User's Coordinator) | H7: SO Contractor (Permit Issuer) | K7: Project Leader HMS/Area Owner (Permit Approver) | M7: *Khusus pekerjaan High Risk, JSA harus direview dan tanda tangan oleh SO HMS di bawah ini | AG7: APD | AH7: Bagian pemotong | AI7: Tidak cukup jarak untuk hidup di bawah tegangan tinggi | AJ7: Lainnya | AK7: Bagian yang bergerak | AL7: Bagian berputar yang tidak seimbang | AM7: lainnya | AN7: Ledakan | AO7: Kerlip, menyilaukan, bayangan, efek stroboscopik | AP7: Kelembapan | AQ7: Tidak mematuhi kebijakan/prosedur | AR7: Objek atau material jatuh | AV7: A | AW7: 4 | AX7: Administrasi Control | AY7: 0.9 | AZ7: Critical | BA7: 8 | BD7: 7-9 | BE7: Critical | BF7: 8 | BG7: Critical | BR7: 1 | BS7: Low | BT7: Low | BU7: Moderate | BV7: High
A8: Nama Customer / User HMS | C8: : Erick Steven L | AH8: Elemen elastis | AI8: Kelebihan beban | AK8: Pengikisan permukaan | AL8: Alat yang bergetar | AN8: Serat | AO8: Postur | AP8: Polusi | AQ8: Mengurangi kapasitas untuk kesehatan mental kerja | AR8: Kemiringan | AX8: APD | AY8: 1 | AZ8: Catastrophic | BA8: 10 | BD8: 9 < | BE8: Catastrophic | BF8: 10 | BG8: Catastrophic
A9: Tanggal / Date | C9: =": "&TEXT(F11,"dd mmm yyyy") -> : 22 Apr 2026 | E9: Nama/Name | F9: M. Fahrur Rozi | H9: Hariyadi Wasis P | AH9: Objek jatuh | AI9: Bagian atau komponen yang menyala/hidup dalam kondisi salah | AK9: Bagian yang berputar tidak seimbang | AL9: Bagian atau komponen aus | AN9: Barang atau bahan mudah terbakar | AO9: Aktivitas berulang | AP9: Salju | AQ9: Mengurangi kapasitas pekerjaan fisik | AR9: Lainnya
A10: Nama & Aktivitas Pekerjaan / Title & Work Activity | C10: : Preventive Maintenance MHE | E10: Sign | AH10: Energi yang tersimpan | AI10: Arus pendek/Short sircuit | AK10: Pneumatic bersiul | AL10: Lainnya | AN10: Cairan | AO10: Postur pengikatan (tidak netral) | AP10: Temperatur/suhu | AQ10: shift kerja
A11: Lokasi Pekerjaan / Work Location | C11: : PILOT PLANT | E11: Tanggal/Date | F11: =TODAY() -> 46134 | H11: =F11 -> 46134 | K11: =H11 -> 46134
A13: № | B13: Tahap Pekerjaan (Sequence of Basic Job Steps) | C13: Hazard Identification and Initial Risk Level | L13: Risk mitigation actions | AH13: Tekanan tinggi | AI13: Radiasi panas | AK13: Bagian atau komponen aus | AN13: Fume | AO13: Upaya dan kekuatan Penanganan Beban (berlebihan, tiba-tiba dan asimetris) | AP13: Air | AQ13: Stres | BH13: QA/QC/Lab | BK13: Kitchen | BM13: LU 23 | BN13: TS
C14: Bahaya (Hazard) | D14: Risiko (Risk) | E14: Deskripsi Bahaya (Hazard Description) | F14: Alat Kerja/Alat Safety yang digunakan (Tool/Safety Tools will use) | G14: Mitigasi Awal (Current Control Measure) | H14: Hirarki Kontrol (Hierarchy of Control) | I14: Keparahan (Severity) | J14: Frekuensi (Likehood) | K14: Level Risiko Awal (Initial Risk level) | L14: Mitigasi Tambahan (Additional Control Measure) | M14: Hirarki Kontrol (Hierarchy of Control) | N14: Penanggung Jawab (Responsible) | O14: Resiko Akhir (Residual risk) | P14: calculation | Q14: Departement | R14: Area / LU | S14: Machine | T14: Equipment | U14: Date | V14: Job | W14: Reaplication | X14: all low | Y14: need support | Z14: Update doc | AA14: HIRADC Triger | AB14: Status Update HIRADC | BM14: LU 24 | BN14: TS / Workshop
B15: Persiapan Kegiatan | K15: =IF(I15="","",VLOOKUP(J15,'Lookup Table (2)'!$O$3:$S$7,MATCH(I15,'Lookup Table (2)'!$O$3:$S$3,0),FALSE)) | O15: =IF(M15="",K15,IF(P15<=3,"Low",IF(AND(3<P15,P15<6),"Moderate",IF(AND(6<=P15,P15<7),"High",IF(AND(7<=P15,P15<=9),"Critical","Catastrophic"))))) | P15: =IF(K15="","",_xlfn.IFNA(VLOOKUP($K15,$AZ$4:$BA$8,2,FALSE)*VLOOKUP($M15,$AX$4:$AY$8,2,FALSE),"")) | Q15: =IF(#REF!="","",$B$5) -> #REF! | R15: =IF(#REF!="","",$B$6) -> #REF! | S15: =IF(#REF!="","",$B$7) -> #REF! | T15: =IF(#REF!="","",$B$8) -> #REF! | U15: =IF(#REF!="","",$B$9) -> #REF! | V15: =IF(#REF!="","",$B$10) -> #REF! | W15: =IF($K$13="yes",1,0) -> 0 | X15: =IF($G$12="yes",1,0) -> 0 | Y15: =IF($G$13="yes",1,0) -> 0 | Z15: =IF($K$12="yes",1,0) -> 0 | AA15: =IF($AV15="","",$AV15) | AB15: =IF($AW15="","",$AW15) | AH15: Mobilitas mesin | AI15: Listrik statis | AK15: Lainnya | AN15: Gas | AO15: Tugas yang tidak bervariasi dan periode pemulihan. | AP15: Angin | AQ15: Kekerasan / Kejahatan
A16: 1 | B16: Briefing dan Pembuatan QRP | E16: Tidak ada karena dilakukan di area aman | K16: =IF(I16="","",VLOOKUP(J16,'Lookup Table (2)'!$O$3:$S$7,MATCH(I16,'Lookup Table (2)'!$O$3:$S$3,0),FALSE)) | O16: =IF(M16="",K16,IF(P16<=3,"Low",IF(AND(3<P16,P16<6),"Moderate",IF(AND(6<=P16,P16<7),"High",IF(AND(7<=P16,P16<=9),"Critical","Catastrophic"))))) | P16: =IF(K16="","",_xlfn.IFNA(VLOOKUP($K16,$AZ$4:$BA$8,2,FALSE)*VLOOKUP($M16,$AX$4:$AY$8,2,FALSE),""))
A17: 2 | B17: Mempersiapkan alat kerja: Toolbox & majun | C17: Bagian peralatan yang menonjol | D17: Tergores | E17: Potensi Tergores sisi tajam alat kerja | F17: Tools, Toolbox | G17: Menggunakan Glove anti gores level 3 | H17: APD | I17: Minor | J17: Rare | K17: =IF(I17="","",VLOOKUP(J17,'Lookup Table (2)'!$O$3:$S$7,MATCH(I17,'Lookup Table (2)'!$O$3:$S$3,0),FALSE)) -> Low | O17: =IF(M17="",K17,IF(P17<=3,"Low",IF(AND(3<P17,P17<6),"Moderate",IF(AND(6<=P17,P17<7),"High",IF(AND(7<=P17,P17<=9),"Critical","Catastrophic"))))) -> Low
A18: 3 | B18: Mempersiapkan area kerja | C18: Forklift dan mesin industri lainnya | D18: Tertabrak | E18: Potensi tertabrak saat pengecekan | G18: Standbyman Memberitahu pekerja di area sekitar | H18: Administrasi Control | I18: Minor | J18: Rare | K18: =IF(I18="","",VLOOKUP(J18,'Lookup Table (2)'!$O$3:$S$7,MATCH(I18,'Lookup Table (2)'!$O$3:$S$3,0),FALSE)) -> Low | O18: =IF(M18="",K18,IF(P18<=3,"Low",IF(AND(3<P18,P18<6),"Moderate",IF(AND(6<=P18,P18<7),"High",IF(AND(7<=P18,P18<=9),"Critical","Catastrophic"))))) -> Low
A19: 4 | B19: Parkir Unit di tempat yang aman | C19: Forklift dan mesin industri lainnya | D19: Tertabrak | E19: Potensi tertabrak / menabrak saat parkir unit | G19: Standbyman Memberitahu pekerja di area sekitar | H19: Administrasi Control | I19: Minor | J19: Rare | K19: =IF(I19="","",VLOOKUP(J19,'Lookup Table (2)'!$O$3:$S$7,MATCH(I19,'Lookup Table (2)'!$O$3:$S$3,0),FALSE)) -> Low | O19: =IF(M19="",K19,IF(P19<=3,"Low",IF(AND(3<P19,P19<6),"Moderate",IF(AND(6<=P19,P19<7),"High",IF(AND(7<=P19,P19<=9),"Critical","Catastrophic"))))) -> Low
B20: Preventive Maintenance Forklift | K20: =IF(I20="","",VLOOKUP(J20,'Lookup Table (2)'!$O$3:$S$7,MATCH(I20,'Lookup Table (2)'!$O$3:$S$3,0),FALSE)) | O20: =IF(M20="",K20,IF(P20<=3,"Low",IF(AND(3<P20,P20<6),"Moderate",IF(AND(6<=P20,P20<7),"High",IF(AND(7<=P20,P20<=9),"Critical","Catastrophic"))))) | P20: =IF(K20="","",_xlfn.IFNA(VLOOKUP($K20,$AZ$4:$BA$8,2,FALSE)*VLOOKUP($M20,$AX$4:$AY$8,2,FALSE),"")) | Q20: =IF(#REF!="","",$B$5) -> #REF! | R20: =IF(#REF!="","",$B$6) -> #REF! | S20: =IF(#REF!="","",$B$7) -> #REF! | T20: =IF(#REF!="","",$B$8) -> #REF! | U20: =IF(#REF!="","",$B$9) -> #REF! | V20: =IF($B$10="","",$B$10) | AA20: =$AV20 -> 0 | AB20: =IF($AW20="","",$AW20) | AH20: Elemen yang bergerak | AI20: Lainnya | AN20: Kabut | AO20: Penanganan yang sering (naikkan, turunkan, dorong, tarik, tahan atau transportasi) | AP20: Visibilitas | AQ20: Mental overload/underload
A21: 1 | B21: Pengecekan Checklist Unit oleh Operator | E21: Tidak ada | O21: =IF(M21="",K21,IF(P21<=3,"Low",IF(AND(3<P21,P21<6),"Moderate",IF(AND(6<=P21,P21<7),"High",IF(AND(7<=P21,P21<=9),"Critical","Catastrophic"))))) -> 0 | P21: =IF(K21="","",_xlfn.IFNA(VLOOKUP($K21,$AZ$4:$BA$8,2,FALSE)*VLOOKUP($M21,$AX$4:$AY$8,2,FALSE),"")) | Q21: =IF(#REF!="","",$B$5) -> #REF! | R21: =IF(#REF!="","",$B$6) -> #REF! | S21: =IF(#REF!="","",$B$7) -> #REF! | T21: =IF(#REF!="","",$B$8) -> #REF! | U21: =IF(#REF!="","",$B$9) -> #REF! | V21: =IF($B$10="","",$B$10) | AA21: =$AV21 -> 0 | AB21: =IF($AW21="","",$AW21) | AH21: Elemen yang berputar | AN21: Oksidasi | AO21: Pekerjaan statik dan pekerjaan berdiri | AP21: Bahaya area kerja yang meningkat | AQ21: Lainnya
A22: 2 | B22: Melepas Kabel koneksi Battery Unit | C22: Bagian peralatan yang menonjol | D22: Tergores | E22: Potensi Tergores bagian socket battery | F22: Glove Anti Gores Level 3 | G22: Menggunakan Glove anti gores level 3 | H22: APD | I22: Minor | J22: Rare | K22: =IF(I22="","",VLOOKUP(J22,'Lookup Table (2)'!$O$3:$S$7,MATCH(I22,'Lookup Table (2)'!$O$3:$S$3,0),FALSE)) -> Low | O22: =IF(M22="",K22,IF(P22<=3,"Low",IF(AND(3<P22,P22<6),"Moderate",IF(AND(6<=P22,P22<7),"High",IF(AND(7<=P22,P22<=9),"Critical","Catastrophic"))))) -> Low
A23: 3 | B23: Pengecekan Visual Kondisi body unit Forklift berkeliling | C23: Forklift dan mesin industri lainnya | D23: Tertabrak | E23: Potensi Tergores bagian forklift | F23: Glove Anti Gores Level 3 | G23: Menggunakan Glove anti gores level 3 | H23: APD | I23: Minor | J23: Rare | K23: =IF(I23="","",VLOOKUP(J23,'Lookup Table (2)'!$O$3:$S$7,MATCH(I23,'Lookup Table (2)'!$O$3:$S$3,0),FALSE)) -> Low | O23: =IF(M23="",K23,IF(P23<=3,"Low",IF(AND(3<P23,P23<6),"Moderate",IF(AND(6<=P23,P23<7),"High",IF(AND(7<=P23,P23<=9),"Critical","Catastrophic"))))) -> Low | P23: =IF(K23="","",_xlfn.IFNA(VLOOKUP($K23,$AZ$4:$BA$8,2,FALSE)*VLOOKUP($M23,$AX$4:$AY$8,2,FALSE),"")) | Q23: =IF(#REF!="","",$B$5) -> #REF! | R23: =IF(#REF!="","",$B$6) -> #REF! | S23: =IF(#REF!="","",$B$7) -> #REF! | T23: =IF(#REF!="","",$B$8) -> #REF! | U23: =IF(#REF!="","",$B$9) -> #REF! | V23: =IF($B$10="","",$B$10) | AA23: =$AV23 -> 0 | AB23: =IF($AW23="","",$AW23) | AH23: Permukaan yang kasar dan licin | AN23: Beracun | AO23: Tekanan mekanis (benda keras) | AP23: Bahaya lalu lintas/pergerakan kendaraan
A24: 4 | B24: Membuka Cover Penutup Deck Forklift dan Cover Battery | C24: Bagian peralatan yang menonjol | D24: Tergores | E24: Potensi Tergores bagian cover deck forklift | F24: Glove Anti Gores Level 3 | G24: Menggunakan Glove anti gores level 3 | H24: APD | I24: Minor | J24: Rare | K24: =IF(I24="","",VLOOKUP(J24,'Lookup Table (2)'!$O$3:$S$7,MATCH(I24,'Lookup Table (2)'!$O$3:$S$3,0),FALSE)) -> Low | O24: =IF(M24="",K24,IF(P24<=3,"Low",IF(AND(3<P24,P24<6),"Moderate",IF(AND(6<=P24,P24<7),"High",IF(AND(7<=P24,P24<=9),"Critical","Catastrophic"))))) -> Low | P24: =IF(K24="","",_xlfn.IFNA(VLOOKUP($K24,$AZ$4:$BA$8,2,FALSE)*VLOOKUP($M24,$AX$4:$AY$8,2,FALSE),"")) | Q24: =IF(#REF!="","",$B$5) -> #REF! | R24: =IF(#REF!="","",$B$6) -> #REF! | S24: =IF(#REF!="","",$B$7) -> #REF! | T24: =IF(#REF!="","",$B$8) -> #REF! | U24: =IF(#REF!="","",$B$9) -> #REF! | V24: =IF($B$10="","",$B$10) | AA24: =$AV24 -> 0 | AB24: =IF($AW24="","",$AW24) | AP24: Ventilasi
A25: 5 | B25: Membuka Cover Penutup Samping Forklift | C25: Bagian peralatan yang menonjol | D25: Tergores | E25: Potensi Tergores bagian cover samping forklift | F25: Glove Anti Gores Level 3 | G25: Menggunakan Glove anti gores level 3 | H25: APD | I25: Minor | J25: Rare | K25: =IF(I25="","",VLOOKUP(J25,'Lookup Table (2)'!$O$3:$S$7,MATCH(I25,'Lookup Table (2)'!$O$3:$S$3,0),FALSE)) -> Low | O25: =IF(M25="",K25,IF(P25<=3,"Low",IF(AND(3<P25,P25<6),"Moderate",IF(AND(6<=P25,P25<7),"High",IF(AND(7<=P25,P25<=9),"Critical","Catastrophic"))))) -> Low | P25: =IF(K25="","",_xlfn.IFNA(VLOOKUP($K25,$AZ$4:$BA$8,2,FALSE)*VLOOKUP($M25,$AX$4:$AY$8,2,FALSE),"")) | Q25: =IF(#REF!="","",$B$5) -> #REF! | R25: =IF(#REF!="","",$B$6) -> #REF! | S25: =IF(#REF!="","",$B$7) -> #REF! | T25: =IF(#REF!="","",$B$8) -> #REF! | U25: =IF(#REF!="","",$B$9) -> #REF! | V25: =IF($B$10="","",$B$10) | AA25: =$AV25 -> 0 | AB25: =IF($AW25="","",$AW25) | AP25: Kebocoran oksigen
A26: 6 | B26: Pre inspection Cleaning dengan Penyemprotan / Vacuum dengan Vacuum Cleaner, Cordless Blower dan majun seluruh bagian Forklift | C26: Debu atau partikel lainnya | D26: Gangguan pernapasan | E26: Debu Terhirup dan terkena mata saat melakukan penyemprotan | F26: Masker | G26: Menggunakan kaca mata safety dan Masker | H26: APD | I26: Minor | J26: Rare | K26: =IF(I26="","",VLOOKUP(J26,'Lookup Table (2)'!$O$3:$S$7,MATCH(I26,'Lookup Table (2)'!$O$3:$S$3,0),FALSE)) -> Low | O26: =IF(M26="",K26,IF(P26<=3,"Low",IF(AND(3<P26,P26<6),"Moderate",IF(AND(6<=P26,P26<7),"High",IF(AND(7<=P26,P26<=9),"Critical","Catastrophic"))))) -> Low | P26: =IF(K26="","",_xlfn.IFNA(VLOOKUP($K26,$AZ$4:$BA$8,2,FALSE)*VLOOKUP($M26,$AX$4:$AY$8,2,FALSE),"")) | Q26: =IF(#REF!="","",$B$5) -> #REF! | R26: =IF(#REF!="","",$B$6) -> #REF! | S26: =IF(#REF!="","",$B$7) -> #REF! | T26: =IF(#REF!="","",$B$8) -> #REF! | U26: =IF(#REF!="","",$B$9) -> #REF! | V26: =IF($B$10="","",$B$10) | AA26: =$AV26 -> 0 | AB26: =IF($AW26="","",$AW26) | AP26: Lainnya
A27: 7 | B27: Pengecekan Kekencangan Baut dan Mur Unit bagian depan | C27: Bagian peralatan yang menonjol | D27: Tergores | E27: Potensi Tergores sisi tajam alat kerja dan unit | F27: Glove Anti Gores Level 3 | G27: Menggunakan Glove anti gores level 3 | H27: APD | I27: Minor | J27: Rare | K27: =IF(I27="","",VLOOKUP(J27,'Lookup Table (2)'!$O$3:$S$7,MATCH(I27,'Lookup Table (2)'!$O$3:$S$3,0),FALSE)) -> Low | O27: =IF(M27="",K27,IF(P27<=3,"Low",IF(AND(3<P27,P27<6),"Moderate",IF(AND(6<=P27,P27<7),"High",IF(AND(7<=P27,P27<=9),"Critical","Catastrophic"))))) -> Low | P27: =IF(K27="","",_xlfn.IFNA(VLOOKUP($K27,$AZ$4:$BA$8,2,FALSE)*VLOOKUP($M27,$AX$4:$AY$8,2,FALSE),"")) | Q27: =IF(#REF!="","",$B$5) -> #REF! | R27: =IF(#REF!="","",$B$6) -> #REF! | S27: =IF(#REF!="","",$B$7) -> #REF! | T27: =IF(#REF!="","",$B$8) -> #REF! | U27: =IF(#REF!="","",$B$9) -> #REF! | V27: =IF($B$10="","",$B$10) | AA27: =$AV27 -> 0 | AB27: =IF($AW27="","",$AW27)
A28: 8 | B28: Pengecekan Kekencangan Baut dan Mur serta kondisi backrest, Fork dan Clamp | C28: Bagian peralatan yang menonjol | D28: Tergores | E28: Potensi Tergores sisi tajam alat kerja dan unit | F28: Glove Anti Gores Level 3 | G28: Menggunakan Glove anti gores level 3 | H28: APD | I28: Minor | J28: Rare | K28: =IF(I28="","",VLOOKUP(J28,'Lookup Table (2)'!$O$3:$S$7,MATCH(I28,'Lookup Table (2)'!$O$3:$S$3,0),FALSE)) -> Low | O28: =IF(M28="",K28,IF(P28<=3,"Low",IF(AND(3<P28,P28<6),"Moderate",IF(AND(6<=P28,P28<7),"High",IF(AND(7<=P28,P28<=9),"Critical","Catastrophic"))))) -> Low | P28: =IF(K28="","",_xlfn.IFNA(VLOOKUP($K28,$AZ$4:$BA$8,2,FALSE)*VLOOKUP($M28,$AX$4:$AY$8,2,FALSE),"")) | Q28: =IF(#REF!="","",$B$5) -> #REF! | R28: =IF(#REF!="","",$B$6) -> #REF! | S28: =IF(#REF!="","",$B$7) -> #REF! | T28: =IF(#REF!="","",$B$8) -> #REF! | U28: =IF(#REF!="","",$B$9) -> #REF! | V28: =IF($B$10="","",$B$10) | AA28: =$AV28 -> 0 | AB28: =IF($AW28="","",$AW28)
A29: 9 | B29: Pengecekan Kondisi Hose clamp, Coupler, dan Boom Clamp | C29: Bagian peralatan yang menonjol | D29: Tergores | E29: Potensi Tergores sisi tajam alat kerja dan unit | F29: Glove Anti Gores Level 3 | G29: Menggunakan Glove anti gores level 3 | H29: APD | I29: Minor | J29: Rare | K29: =IF(I29="","",VLOOKUP(J29,'Lookup Table (2)'!$O$3:$S$7,MATCH(I29,'Lookup Table (2)'!$O$3:$S$3,0),FALSE)) -> Low | O29: =IF(M29="",K29,IF(P29<=3,"Low",IF(AND(3<P29,P29<6),"Moderate",IF(AND(6<=P29,P29<7),"High",IF(AND(7<=P29,P29<=9),"Critical","Catastrophic"))))) -> Low | P29: =IF(K29="","",_xlfn.IFNA(VLOOKUP($K29,$AZ$4:$BA$8,2,FALSE)*VLOOKUP($M29,$AX$4:$AY$8,2,FALSE),"")) | Q29: =IF(#REF!="","",$B$5) -> #REF! | R29: =IF(#REF!="","",$B$6) -> #REF! | S29: =IF(#REF!="","",$B$7) -> #REF! | T29: =IF(#REF!="","",$B$8) -> #REF! | U29: =IF(#REF!="","",$B$9) -> #REF! | V29: =IF($B$10="","",$B$10) | AA29: =$AV29 -> 0 | AB29: =IF($AW29="","",$AW29)
A30: 10 | B30: Greasing Pada Bagian Greasing Point Clamp | C30: Bagian peralatan yang menonjol | D30: Tergores | E30: Potensi Tergores sisi tajam alat kerja dan unit | F30: Glove Anti Gores Level 3 | G30: Menggunakan Glove anti gores level 3 | H30: APD | I30: Minor | J30: Rare | K30: =IF(I30="","",VLOOKUP(J30,'Lookup Table (2)'!$O$3:$S$7,MATCH(I30,'Lookup Table (2)'!$O$3:$S$3,0),FALSE)) -> Low | O30: =IF(M30="",K30,IF(P30<=3,"Low",IF(AND(3<P30,P30<6),"Moderate",IF(AND(6<=P30,P30<7),"High",IF(AND(7<=P30,P30<=9),"Critical","Catastrophic"))))) -> Low | P30: =IF(K30="","",_xlfn.IFNA(VLOOKUP($K30,$AZ$4:$BA$8,2,FALSE)*VLOOKUP($M30,$AX$4:$AY$8,2,FALSE),"")) | Q30: =IF(#REF!="","",$B$5) -> #REF! | R30: =IF(#REF!="","",$B$6) -> #REF! | S30: =IF(#REF!="","",$B$7) -> #REF! | T30: =IF(#REF!="","",$B$8) -> #REF! | U30: =IF(#REF!="","",$B$9) -> #REF! | V30: =IF($B$10="","",$B$10) | AA30: =$AV30 -> 0 | AB30: =IF($AW30="","",$AW30)
A31: 11 | B31: Pengecekan Kondisi Mast dan bearing Mast | C31: Bagian peralatan yang menonjol | D31: Tergores | E31: Potensi Tergores sisi tajam alat kerja dan unit | F31: Glove Anti Gores Level 3 | G31: Menggunakan Glove anti gores level 3 | H31: APD | I31: Minor | J31: Rare | K31: =IF(I31="","",VLOOKUP(J31,'Lookup Table (2)'!$O$3:$S$7,MATCH(I31,'Lookup Table (2)'!$O$3:$S$3,0),FALSE)) -> Low | O31: =IF(M31="",K31,IF(P31<=3,"Low",IF(AND(3<P31,P31<6),"Moderate",IF(AND(6<=P31,P31<7),"High",IF(AND(7<=P31,P31<=9),"Critical","Catastrophic"))))) -> Low | P31: =IF(K31="","",_xlfn.IFNA(VLOOKUP($K31,$AZ$4:$BA$8,2,FALSE)*VLOOKUP($M31,$AX$4:$AY$8,2,FALSE),"")) | Q31: =IF(#REF!="","",$B$5) -> #REF! | R31: =IF(#REF!="","",$B$6) -> #REF! | S31: =IF(#REF!="","",$B$7) -> #REF! | T31: =IF(#REF!="","",$B$8) -> #REF! | U31: =IF(#REF!="","",$B$9) -> #REF! | V31: =IF($B$10="","",$B$10) | AA31: =$AV31 -> 0 | AB31: =IF($AW31="","",$AW31)
A32: 12 | B32: Greasing Pada Bagian Greasing Point Mast | C32: Bagian peralatan yang menonjol | D32: Tergores | E32: Potensi Tergores sisi tajam alat kerja dan unit | F32: Glove Anti Gores Level 3 | G32: Menggunakan Glove anti gores level 3 | H32: APD | I32: Minor | J32: Rare | K32: =IF(I32="","",VLOOKUP(J32,'Lookup Table (2)'!$O$3:$S$7,MATCH(I32,'Lookup Table (2)'!$O$3:$S$3,0),FALSE)) -> Low | O32: =IF(M32="",K32,IF(P32<=3,"Low",IF(AND(3<P32,P32<6),"Moderate",IF(AND(6<=P32,P32<7),"High",IF(AND(7<=P32,P32<=9),"Critical","Catastrophic"))))) -> Low | P32: =IF(K32="","",_xlfn.IFNA(VLOOKUP($K32,$AZ$4:$BA$8,2,FALSE)*VLOOKUP($M32,$AX$4:$AY$8,2,FALSE),"")) | Q32: =IF(#REF!="","",$B$5) -> #REF! | R32: =IF(#REF!="","",$B$6) -> #REF! | S32: =IF(#REF!="","",$B$7) -> #REF! | T32: =IF(#REF!="","",$B$8) -> #REF! | U32: =IF(#REF!="","",$B$9) -> #REF! | V32: =IF($B$10="","",$B$10) | AA32: =$AV32 -> 0 | AB32: =IF($AW32="","",$AW32)
A33: 13 | B33: Pengecekan Visual boom hidrolik Tilt dan Lift | C33: Bagian peralatan yang menonjol | D33: Tergores | E33: Potensi Tergores sisi tajam alat kerja dan unit | F33: Glove Anti Gores Level 3 | G33: Menggunakan Glove anti gores level 3 | H33: APD | I33: Minor | J33: Rare | K33: =IF(I33="","",VLOOKUP(J33,'Lookup Table (2)'!$O$3:$S$7,MATCH(I33,'Lookup Table (2)'!$O$3:$S$3,0),FALSE)) -> Low | O33: =IF(M33="",K33,IF(P33<=3,"Low",IF(AND(3<P33,P33<6),"Moderate",IF(AND(6<=P33,P33<7),"High",IF(AND(7<=P33,P33<=9),"Critical","Catastrophic"))))) -> Low | P33: =IF(K33="","",_xlfn.IFNA(VLOOKUP($K33,$AZ$4:$BA$8,2,FALSE)*VLOOKUP($M33,$AX$4:$AY$8,2,FALSE),"")) | Q33: =IF(#REF!="","",$B$5) -> #REF! | R33: =IF(#REF!="","",$B$6) -> #REF! | S33: =IF(#REF!="","",$B$7) -> #REF! | T33: =IF(#REF!="","",$B$8) -> #REF! | U33: =IF(#REF!="","",$B$9) -> #REF! | V33: =IF($B$10="","",$B$10) | AA33: =$AV33 -> 0 | AB33: =IF($AW33="","",$AW33)
A34: 14 | B34: Pengecekan Tekanan ban dan TWI | C34: Bagian peralatan yang menonjol | D34: Tergores | E34: Potensi Tergores sisi tajam alat kerja dan unit | F34: Glove Anti Gores Level 3 | G34: Menggunakan Glove anti gores level 3 | H34: APD | I34: Minor | J34: Rare | K34: =IF(I34="","",VLOOKUP(J34,'Lookup Table (2)'!$O$3:$S$7,MATCH(I34,'Lookup Table (2)'!$O$3:$S$3,0),FALSE)) -> Low | O34: =IF(M34="",K34,IF(P34<=3,"Low",IF(AND(3<P34,P34<6),"Moderate",IF(AND(6<=P34,P34<7),"High",IF(AND(7<=P34,P34<=9),"Critical","Catastrophic"))))) -> Low | P34: =IF(K34="","",_xlfn.IFNA(VLOOKUP($K34,$AZ$4:$BA$8,2,FALSE)*VLOOKUP($M34,$AX$4:$AY$8,2,FALSE),""))
A35: 15 | B35: Pengecekan Kondisi velg dan kekencangan Baut Roda, Baut Velg | C35: Bagian peralatan yang menonjol | D35: Tergores | E35: Potensi Tergores sisi tajam alat kerja dan unit | F35: Glove Anti Gores Level 3 | G35: Menggunakan Glove anti gores level 3 | H35: APD | I35: Minor | J35: Rare | O35: =IF(M35="",K35,IF(P35<=3,"Low",IF(AND(3<P35,P35<6),"Moderate",IF(AND(6<=P35,P35<7),"High",IF(AND(7<=P35,P35<=9),"Critical","Catastrophic"))))) -> 0
A36: 16 | B36: Pengecekan Level Minyak Rem dan Hose Rem | C36: Bahan Kimia berbahaya | D36: Iritasi kulit atau mata | E36: Potensi iritasi pada tangan saat melakukan pengecekan | F36: Glove Kimia | G36: Menggunakan Glove Kima | H36: APD | I36: Minor | J36: Rare | K36: =IF(I36="","",VLOOKUP(J36,'Lookup Table (2)'!$O$3:$S$7,MATCH(I36,'Lookup Table (2)'!$O$3:$S$3,0),FALSE)) -> Low | O36: =IF(M36="",K36,IF(P36<=3,"Low",IF(AND(3<P36,P36<6),"Moderate",IF(AND(6<=P36,P36<7),"High",IF(AND(7<=P36,P36<=9),"Critical","Catastrophic"))))) -> Low | P36: =IF(K36="","",_xlfn.IFNA(VLOOKUP($K36,$AZ$4:$BA$8,2,FALSE)*VLOOKUP($M36,$AX$4:$AY$8,2,FALSE),""))
A37: 17 | B37: Pengecekan Level Oli Hidrolis dan Kondisi Tangki Hidrolis | C37: Bahan Kimia berbahaya | D37: Iritasi kulit atau mata | E37: Potensi iritasi pada tangan saat melakukan pengecekan | F37: Glove Kimia | G37: Menggunakan Glove Kima | H37: APD | I37: Minor | J37: Rare | K37: =IF(I37="","",VLOOKUP(J37,'Lookup Table (2)'!$O$3:$S$7,MATCH(I37,'Lookup Table (2)'!$O$3:$S$3,0),FALSE)) -> Low | O37: =IF(M37="",K37,IF(P37<=3,"Low",IF(AND(3<P37,P37<6),"Moderate",IF(AND(6<=P37,P37<7),"High",IF(AND(7<=P37,P37<=9),"Critical","Catastrophic"))))) -> Low
A38: 18 | B38: Pengecekan Jalur Hose Hydraulic | C38: Bagian peralatan yang menonjol | D38: Tergores | E38: Potensi Tergores sisi tajam alat kerja dan unit | F38: Glove Anti Gores Level 3 | G38: Menggunakan Glove anti gores level 3 | H38: APD | I38: Minor | J38: Rare | K38: =IF(I38="","",VLOOKUP(J38,'Lookup Table (2)'!$O$3:$S$7,MATCH(I38,'Lookup Table (2)'!$O$3:$S$3,0),FALSE)) -> Low | O38: =IF(M38="",K38,IF(P38<=3,"Low",IF(AND(3<P38,P38<6),"Moderate",IF(AND(6<=P38,P38<7),"High",IF(AND(7<=P38,P38<=9),"Critical","Catastrophic"))))) -> Low | P38: =IF(K38="","",_xlfn.IFNA(VLOOKUP($K38,$AZ$4:$BA$8,2,FALSE)*VLOOKUP($M38,$AX$4:$AY$8,2,FALSE),""))
A39: 19 | B39: Pengecekan Fisik Kelistrikan | C39: Bagian peralatan yang menonjol | D39: Tergores | E39: Potensi Tergores sisi tajam alat kerja dan unit | F39: Glove Anti Gores Level 3 | G39: Menggunakan Glove anti gores level 3 | H39: APD | I39: Minor | J39: Rare | K39: =IF(I39="","",VLOOKUP(J39,'Lookup Table (2)'!$O$3:$S$7,MATCH(I39,'Lookup Table (2)'!$O$3:$S$3,0),FALSE)) -> Low | O39: =IF(M39="",K39,IF(P39<=3,"Low",IF(AND(3<P39,P39<6),"Moderate",IF(AND(6<=P39,P39<7),"High",IF(AND(7<=P39,P39<=9),"Critical","Catastrophic"))))) -> Low
A40: 20 | B40: Pengecekan Visual Drive Motor dan Hydraulic Motor | C40: Bagian peralatan yang menonjol | D40: Tergores | E40: Potensi Tergores sisi tajam alat kerja dan unit | F40: Glove Anti Gores Level 3 | G40: Menggunakan Glove anti gores level 3 | H40: APD | I40: Minor | J40: Rare | K40: =IF(I40="","",VLOOKUP(J40,'Lookup Table (2)'!$O$3:$S$7,MATCH(I40,'Lookup Table (2)'!$O$3:$S$3,0),FALSE)) -> Low | O40: =IF(M40="",K40,IF(P40<=3,"Low",IF(AND(3<P40,P40<6),"Moderate",IF(AND(6<=P40,P40<7),"High",IF(AND(7<=P40,P40<=9),"Critical","Catastrophic"))))) -> Low | P40: =IF(K40="","",_xlfn.IFNA(VLOOKUP($K40,$AZ$4:$BA$8,2,FALSE)*VLOOKUP($M40,$AX$4:$AY$8,2,FALSE),""))
A41: 21 | B41: Pengecekan Visual Control Valve | C41: Bagian peralatan yang menonjol | D41: Tergores | E41: Potensi Tergores sisi tajam alat kerja dan unit | F41: Glove Anti Gores Level 3 | G41: Menggunakan Glove anti gores level 3 | H41: APD | I41: Minor | J41: Rare | K41: =IF(I41="","",VLOOKUP(J41,'Lookup Table (2)'!$O$3:$S$7,MATCH(I41,'Lookup Table (2)'!$O$3:$S$3,0),FALSE)) -> Low | O41: =IF(M41="",K41,IF(P41<=3,"Low",IF(AND(3<P41,P41<6),"Moderate",IF(AND(6<=P41,P41<7),"High",IF(AND(7<=P41,P41<=9),"Critical","Catastrophic"))))) -> Low | P41: =IF(K41="","",_xlfn.IFNA(VLOOKUP($K41,$AZ$4:$BA$8,2,FALSE)*VLOOKUP($M41,$AX$4:$AY$8,2,FALSE),""))
A42: 22 | B42: Pengecekan Kondisi Bearing, Knuckle, Axle Sensor dan Tie Rod | C42: Bagian peralatan yang menonjol | D42: Tergores | E42: Potensi Tergores sisi tajam alat kerja dan unit | F42: Glove Anti Gores Level 3 | G42: Menggunakan Glove anti gores level 3 | H42: APD | I42: Minor | J42: Rare | K42: =IF(I42="","",VLOOKUP(J42,'Lookup Table (2)'!$O$3:$S$7,MATCH(I42,'Lookup Table (2)'!$O$3:$S$3,0),FALSE)) -> Low | O42: =IF(M42="",K42,IF(P42<=3,"Low",IF(AND(3<P42,P42<6),"Moderate",IF(AND(6<=P42,P42<7),"High",IF(AND(7<=P42,P42<=9),"Critical","Catastrophic"))))) -> Low | P42: =IF(K42="","",_xlfn.IFNA(VLOOKUP($K42,$AZ$4:$BA$8,2,FALSE)*VLOOKUP($M42,$AX$4:$AY$8,2,FALSE),""))
...

Sheet Listis
A1: Hazard list | B1: Risks | C1: Severity | D1: Probability | E1: Risk evaluation
A2: Akses yang sempit | B2: Cedera | C2: Minor | D2: Rare | E2: Low
A3: Asbestos | B3: Dehidrasi | C3: Moderate | D3: Unlikely | E3: Moderate
A4: Automatic start | B4: Dislokasi | C4: Serious | D4: Likely | E4: High
A5: Bagian peralatan yang menonjol | B5: Gangguan pendengaran | C5: Catastrophic | D5: Almost certain | E5: Critical
A6: Bagian yang bergerak | B6: Gangguan penglihatan | E6: Catastrophic
A7: Bahan Kimia berbahaya | B7: Gangguan pernapasan
A8: Bahan peledak | B8: Hand Arm Vibration Syndrom
A9: Bahaya listrik | B9: Hipotermia
A10: Bahaya suhu rendah | B10: Iritasi
A11: Bahaya suhu tinggi | B11: Kanker/Kerusakan Sel
A12: Baterai isi ulang | B12: Kebakaran
A13: Beban di atas kepala | B13: Kebutaan
A14: Beban pengangkatan tidak pada titik center | B14: Kehilangan kesadaran
A15: Bekerja di area lalu-lalang kendaraan | B15: Kekurangan nafas
A16: Bekerja di ketinggian | B16: Kelelahan
A17: Benda jatuh | B17: Keracunan
A18: Compressed gas / air | B18: Korosi
... A39: Permukaan panas | B39: Tremor
A40: Posisi tubuh tidak aman
A41: Radiasi Optik
A42: Sinar laser
A43: Stress berhubungan dengan pekerjaan
A44: Struktur di atas kepala
A45: Tidak ada
A46: Tools / Peralatan
A47: Zat beracun
A48: Zat karsinogenik dan mutagenik
A49: Zat kaustid dan korosif
A50: zat yang mudah terbakar
A51: Pekerjaan Panas
A52: Area ATEX

Sheet New Listis 
A1: Akses yang sempit | B1: Asbestos | C1: Bagian peralatan yang menonjol | D1: Bagian yang bergerak | E1: Bahan Kimia berbahaya | F1: Bahan peledak | G1: Bahaya listrik | H1: Bahaya suhu rendah | I1: Bahaya suhu tinggi | J1: Beban di atas kepala | K1: Beban pengangkatan tidak pada titik center | L1: Bekerja di area lalu lalang kendaraan | M1: Bekerja di ketinggian | N1: Benda jatuh | O1: Compressed gas atau air | P1: Dampak Biologi | Q1: Debu atau partikel lainnya | R1: Elemen tajam | S1: Flashes atau Sinar Berkedip | T1: Forklift dan mesin industri lainnya | U1: Gerakan anggot tubuh ke atas yang berulang | V1: Gesekan | W1: Getaran pada tangan | X1: Getaran pada tubuh | Y1: Halangan di atas kepala | Z1: Kebisingan | AA1: Material radioaktif | AB1: Manual Handling | AC1: Penerangan | AD1: Permukaan dingin | AE1: Permukaan licin | AF1: Permukaan panas | AG1: Stress berhubungan dengan pekerjaan | AH1: Peralatan belum di cek | AI1: zat yang mudah terbakar | AJ1: Pekerjaan panas | AK1: Area ATEX | AL1: Ruang Terbatas
A2: Terbentur | B2: Asbestositosis | C2: Terbentur | D2: Terjepit | E2: Iritasi kulit atau mata | F2: Ledakan | G2: Tersengat listrik | H2: Hipotermia | I2: Dehidrasi | J2: Terbentur | K2: Property Damage | L2: Tertabrak | M2: Terjatuh | N2: Tertimpa | O2: Paparan gas | P2: Penyakit akibat kerja | Q2: Gangguan pernapasan | R2: Tergores | S2: Iritasi mata | T2: Tertabrak | U2: Nyeri Otot | V2: Tergores | W2: Tremor | X2: Hand Arm Vibration Syndrom | Y2: Terbentur | Z2: Gangguan pendengaran | AA2: Kanker | AB2: Nyeri otot | AC2: Gangguan penglihatan | AD2: Frostbite | AE2: Terpeleset | AF2: Kulit melepuh | AG2: Tidak fokus | AH2: Peralatan rusak | AI2: Kebakaran | AJ2: Kebakaran | AK2: Kebakaran | AL2: Terperangkap
A3: Terhimpit | B3: Sesak napas | C3: Tergores | D3: Tersayat | E3: Keracunan | F3: Kebakran | G3: Kebakaran | I3: Kulit melepuh | J3: Tertimpa | K3: Tertimpa | L3: Property Damage | M3: Terbentur | N3: Property damage | O3: Cedera fisik | P3: Keracunan | Q3: Iritasi mata | R3: Tersayat | S3: Gangguan stabilitas (vertigo/pusing) | T3: Terbentur | U3: Kram | W3: Nyeri otot | AB3: Tertimpa | AD3: Luka bakar dingin | AG3: Kelelahan | AJ3: Ledakan | AK3: Ledakan | AL3: Terhimpit
A4: Kelelahan | C4: Tersandung | D4: Tergores | E4: Ledakan | I4: Kelelahan | Q4: Terpeleset | R4: Terpotong | T4: Property Damage | AB4: Tergores | AD4: Hipotermia | AJ4: Kulit melepuh | AL4: Kekurangan napas
A5: Terjepit | E5: Kebakaran | Q5: Kebakaran
A6: Kekurangan napas | E6: Gangguan pernafasan
A7: Terperangkap | E7: Kulit melepuh
E8: Pencemaran Lingkungan
